{"timestamp": "2025-09-16T09:52:17.532486", "module": "vega.error_test", "level": "ERROR", "function": "test_error_logging_with_exception", "line": 255, "message": "An error occurred", "thread": 137537835225408, "process": 3370757, "exception": "Traceback (most recent call last):\n  File \"/home/ncacord/Vega2.0/tests/test_logging.py\", line 253, in test_error_logging_with_exception\n    raise ValueError(\"Test exception\")\nValueError: Test exception\n", "extra_taskName": null, "extra_message": "An error occurred", "extra_asctime": "2025-09-16 04:52:17"}
